<?xml version="1.0" encoding="utf-8"?>
<!-- This URDF was automatically created by SolidWorks to URDF Exporter! Originally created by Stephen Brawner (brawner@gmail.com) 
     Commit Version: 1.6.0-1-g15f4949  Build Version: 1.6.7594.29634
     For more information, please see http://wiki.ros.org/sw_urdf_exporter -->
<robot
  name="UR3">
  
  <link name="world" />
  <joint name="world_joint" type="fixed">
    <parent link="world" />
    <child link = "base_link" />
    <origin xyz="0.0 0.0 0.0" rpy="3.1415926536 3.1415926536 0.0" />
  </joint>
  
  <link
    name="base_link">
    <inertial>
      <origin
        xyz="3.8372E-05 -0.00080955 0.04622"
        rpy="0 0 0" />
      <mass
        value="0.61578" />
      <inertia
        ixx="0.00076129"
        ixy="2.9387E-07"
        ixz="3.4791E-07"
        iyy="0.00077457"
        iyz="-3.4742E-06"
        izz="0.0010029" />
    </inertial>
    <visual>
      <origin
        xyz="0 0 0"
        rpy="0 0 0" />
      <geometry>
        <mesh
          filename="package://UR3/meshes/base_link.STL" />
      </geometry>
      <material
        name="Grey">
        <color
          rgba="0.4 0.4 0.4 1.0"/>
		<texture
          filename="package://UR3/textures/0.png" />
      </material>
    </visual>
    <collision>
      <origin
        xyz="0 0 0"
        rpy="0 0 0" />
      <geometry>
        <mesh
          filename="package://UR3/meshes/base_link.STL" />
      </geometry>
    </collision>
  </link>
  <link
    name="shoulder_link">
    <inertial>
      <origin
        xyz="6.6134E-06 0.0072751 -0.01157"
        rpy="0 0 0" />
      <mass
        value="0.75496" />
      <inertia
        ixx="0.0010673"
        ixy="-1.7198E-07"
        ixz="1.2409E-07"
        iyy="0.00098991"
        iyz="-0.00013061"
        izz="0.00090487" />
    </inertial>
    <visual>
      <origin
        xyz="0 0 0"
        rpy="0 0 0" />
      <geometry>
        <mesh
          filename="package://UR3/meshes/shoulder_link.STL" />
      </geometry>
      <material
        name="Orange">
        <color
          rgba="1.0 0.423529411765 0.0392156862745 1.0" />
		<texture
          filename="package://UR3/textures/1.png" />
      </material>
    </visual>
    <collision>
      <origin
        xyz="0 0 0"
        rpy="0 0 0" />
      <geometry>
        <mesh
          filename="package://UR3/meshes/shoulder_link.STL" />
      </geometry>
    </collision>
  </link>
  <joint
    name="shoulder_pan_joint"
    type="revolute">
    <origin
      xyz="0 0 0.1519"
      rpy="0 0 0" />
    <parent
      link="base_link" />
    <child
      link="shoulder_link" />
    <axis
      xyz="0 0 1" />
    <limit
      lower="-3.14"
      upper="3.14"
      effort="150"
      velocity="1.57" />
  </joint>
  <link
    name="upper_arm_link">
    <inertial>
      <origin
        xyz="-2.7508E-06 -0.0032541 0.10568"
        rpy="0 0 0" />
      <mass
        value="1.8002" />
      <inertia
        ixx="0.0026472"
        ixy="-1.2054E-07"
        ixz="1.7542E-07"
        iyy="0.0025148"
        iyz="-8.0826E-05"
        izz="0.0016697" />
    </inertial>
    <visual>
      <origin
        xyz="0 0 0"
        rpy="0 0 0" />
      <geometry>
        <mesh
          filename="package://UR3/meshes/upper_arm_link.STL" />
      </geometry>
      <material
        name="Orange">
        <color
          rgba="1.0 0.423529411765 0.0392156862745 1.0" />
		<texture
          filename="package://UR3/textures/2.png" />
      </material>
    </visual>
    <collision>
      <origin
        xyz="0 0 0"
        rpy="0 0 0" />
      <geometry>
        <mesh
          filename="package://UR3/meshes/upper_arm_link.STL" />
      </geometry>
    </collision>
  </link>
  <joint
    name="shoulder_lift_join"
    type="revolute">
    <origin
      xyz="0 0.11985 0"
      rpy="0 0 0" />
    <parent
      link="shoulder_link" />
    <child
      link="upper_arm_link" />
    <axis
      xyz="0 1 0" />
    <limit
      lower="-3.14"
      upper="3.14"
      effort="150"
      velocity="1.57" />
  </joint>
  <link
    name="forearm_link">
    <inertial>
      <origin
        xyz="1.86130767464698E-06 0.0050504102156036 0.111203258131293"
        rpy="0 0 0" />
      <mass
        value="0.962327239849504" />
      <inertia
        ixx="0.0010727233594452"
        ixy="1.86933270066241E-09"
        ixz="-6.59035926251097E-10"
        iyy="0.00101484199720974"
        iyz="4.61391602068538E-05"
        izz="0.000542735149271365" />
    </inertial>
    <visual>
      <origin
        xyz="0 0 0"
        rpy="0 0 0" />
      <geometry>
        <mesh
          filename="package://UR3/meshes/forearm_link.STL" />
      </geometry>
      <material
        name="Orange">
        <color
          rgba="1.0 0.423529411765 0.0392156862745 1.0" />
		<texture
          filename="package://UR3/textures/3.png" />
      </material>
    </visual>
    <collision>
      <origin
        xyz="0 0 0"
        rpy="0 0 0" />
      <geometry>
        <mesh
          filename="package://UR3/meshes/forearm_link.STL" />
      </geometry>
    </collision>
  </link>
  <joint
    name="elbow_joint"
    type="revolute">
    <origin
      xyz="0 -0.093211 0.24365"
      rpy="0 0 0" />
    <parent
      link="upper_arm_link" />
    <child
      link="forearm_link" />
    <axis
      xyz="0 1 0" />
    <limit
      lower="-3.14"
      upper="3.14"
      effort="150"
      velocity="1.57" />
  </joint>
  <link
    name="wrist_1_link">
    <inertial>
      <origin
        xyz="-5.7002E-06 0.081177 -0.0007955"
        rpy="0 0 0" />
      <mass
        value="0.32531" />
      <inertia
        ixx="0.00022623"
        ixy="3.2028E-10"
        ixz="-9.1012E-10"
        iyy="0.0001946"
        iyz="-1.8337E-05"
        izz="0.00019911" />
    </inertial>
    <visual>
      <origin
        xyz="0 0 0"
        rpy="0 0 0" />
      <geometry>
        <mesh
          filename="package://UR3/meshes/wrist_1_link.STL" />
      </geometry>
      <material
        name="Orange">
        <color
          rgba="1.0 0.423529411765 0.0392156862745 1.0" />
		<texture
          filename="package://UR3/textures/4.png" />
      </material>
    </visual>
    <collision>
      <origin
        xyz="0 0 0"
        rpy="0 0 0" />
      <geometry>
        <mesh
          filename="package://UR3/meshes/wrist_1_link.STL" />
      </geometry>
    </collision>
  </link>
  <joint
    name="wrist_1_joint"
    type="revolute">
    <origin
      xyz="0 0 0.213"
      rpy="0 0 0" />
    <parent
      link="forearm_link" />
    <child
      link="wrist_1_link" />
    <axis
      xyz="0 1 0" />
    <limit
      lower="-3.14"
      upper="3.14"
      effort="28"
      velocity="3.14" />
  </joint>
  <link
    name="wrist_2_link">
    <inertial>
      <origin
        xyz="5.7002E-06 -0.0007955 0.081177"
        rpy="0 0 0" />
      <mass
        value="0.32531" />
      <inertia
        ixx="0.00022623"
        ixy="4.0289E-10"
        ixz="4.8635E-10"
        iyy="0.00019911"
        iyz="-1.8337E-05"
        izz="0.0001946" />
    </inertial>
    <visual>
      <origin
        xyz="0 0 0"
        rpy="0 0 0" />
      <geometry>
        <mesh
          filename="package://UR3/meshes/wrist_2_link.STL" />
      </geometry>
      <material
        name="Orange">
        <color
          rgba="1.0 0.423529411765 0.0392156862745 1.0" />
		<texture
          filename="package://UR3/textures/5.png" />
      </material>
    </visual>
    <collision>
      <origin
        xyz="0 0 0"
        rpy="0 0 0" />
      <geometry>
        <mesh
          filename="package://UR3/meshes/wrist_2_link.STL" />
      </geometry>
    </collision>
  </link>
  <joint
    name="wrist_2_joint"
    type="revolute">
    <origin
      xyz="0 0.0871 0"
      rpy="0 0 0" />
    <parent
      link="wrist_1_link" />
    <child
      link="wrist_2_link" />
    <axis
      xyz="0 0 1" />
    <limit
      lower="-3.14"
      upper="3.14"
      effort="28"
      velocity="3.14" />
  </joint>
  <link
    name="wrist_3_link">
    <inertial>
      <origin
        xyz="-9.3892E-05 0.061173 4.3066E-05"
        rpy="0 0 0" />
      <mass
        value="0.11536" />
      <inertia
        ixx="4.2644E-05"
        ixy="9.3825E-08"
        ixz="-8.0577E-08"
        iyy="5.9067E-05"
        iyz="-4.3032E-08"
        izz="4.2506E-05" />
    </inertial>
    <visual>
      <origin
        xyz="0 0 0"
        rpy="0 0 0" />
      <geometry>
        <mesh
          filename="package://UR3/meshes/wrist_3_link.STL" />
      </geometry>
      <material
        name="Red">
        <color
          rgba="0.8 0.0 0.0 1.0"/>
		<texture
          filename="package://UR3/textures/6.png" />
      </material>
    </visual>
    <collision>
      <origin
        xyz="0 0 0"
        rpy="0 0 0" />
      <geometry>
        <mesh
          filename="package://UR3/meshes/wrist_3_link.STL" />
      </geometry>
    </collision>
  </link>
  <joint
    name="wrist_3_joint"
    type="revolute">
    <origin
      xyz="0 0 0.0871"
      rpy="0 0 0" />
    <parent
      link="wrist_2_link" />
    <child
      link="wrist_3_link" />
    <axis
      xyz="0 1 0" />
    <limit
      lower="-3.14"
      upper="3.14"
      effort="28"
      velocity="3.14" />
  </joint>
  
  <!--new add content -->
  <link name="ee_link">
    <collision>
      <geometry>
        <box size="0.01 0.01 0.01"/>
      </geometry>
      <origin rpy="0 0 0" xyz="-0.01 0 0"/>
    </collision>
  </link>
  
  <joint name="ee_fixed_joint" type="fixed">
    <parent link="wrist_3_link"/>
    <child link="ee_link"/>
    <origin rpy="0.0 0.0 1.57079632679" xyz="0.0 0.04436 0.0"/>
  </joint>
  
	
      <!-- Frame coincident with all-zeros TCP on ROCR6 controller -->
  <link name="tool0"/>
  <joint name="wrist_3_link-tool0_fixed_joint" type="fixed">
    <origin rpy="-1.57079632679 0 0" xyz="0 0.04436 0"/>
    <parent link="wrist_3_link"/>
    <child link="tool0"/>
  </joint>
</robot>